Workbook

Sheet 検索
A1: ① 医薬品名 → 薬効分類名 検索 | G1: 内部計算用（編集・削除しないでください）
A2: 黄色いセルに医薬品名（品名または成分名。部分入力も可）を入力すると、薬価基準収載医薬品コードの左3桁から薬効分類名を表示します。 | H2: =IFERROR(MATCH("*"&ASC($B$5)&"*",医薬品マスタ!$N$2:$N$8936,0),"") -> 1
H3: =IFERROR(MATCH("*"&ASC($B$5)&"*",医薬品マスタ!$O$2:$O$8936,0),"") -> 1
A5: 医薬品名を入力 | H5: =IF($B$5="","",IF(H2<>"",H2,IF(H3<>"",H3,"")))
A7: 薬効分類名 | B7: =IF($B$5="","",IF($H$5="","該当する医薬品が見つかりませんでした。名称の一部を短くするか、別の表記でお試しください。",IFERROR(INDEX(薬効分類マスタ!$B$2:$B$180,MATCH($B$14,薬効分類マスタ!$A$2:$A$180,0)),"分類コードが薬効分類マスタに未登録です")))
A10: 該当した品名 | B10: =IF($H$5="","",INDEX(医薬品マスタ!$G$2:$G$8936,$H$5))
A11: 規格 | B11: =IF($H$5="","",INDEX(医薬品マスタ!$F$2:$F$8936,$H$5))
A12: 成分名 | B12: =IF($H$5="","",INDEX(医薬品マスタ!$E$2:$E$8936,$H$5))
A13: 薬価基準収載医薬品コード | B13: =IF($H$5="","",INDEX(医薬品マスタ!$B$2:$B$8936,$H$5))
A14: 薬効分類コード（左3桁） | B14: =IF($B$13="","",VALUE(LEFT($B$13,3)))
A15: 区分（内用薬/外用薬） | B15: =IF($H$5="","",INDEX(医薬品マスタ!$A$2:$A$8936,$H$5))
A16: 薬価 | B16: =IF($H$5="","",INDEX(医薬品マスタ!$I$2:$I$8936,$H$5))
A17: 対象区分（アプリ用） | B17: =IF($H$5="","",INDEX(医薬品マスタ!$K$2:$K$8936,$H$5))
A19: ※ 同じ名称で複数の医薬品が存在する場合は、最初に見つかった1件を表示します。
A23: ② 薬効分類を探す（キーワード or コード）
A24: 黄色いセルに薬効分類名の一部（例: 抗菌、グラム、解熱）または分類コード（例: 61、114）を入力すると、該当する薬効分類を最大15件まで表示します。
A25: キーワード/コード
A27: 薬効分類コード | B27: 薬効分類名 | C27: 内用薬の件数 | D27: 外用薬の件数 | E27: 対象区分
A28: =IFERROR(INDEX(薬効分類マスタ!$A$2:$A$180,MATCH(1,薬効分類マスタ!$H$2:$H$180,0)),"") | B28: =IFERROR(INDEX(薬効分類マスタ!$B$2:$B$180,MATCH(1,薬効分類マスタ!$H$2:$H$180,0)),"") | C28: =IFERROR(INDEX(薬効分類マスタ!$C$2:$C$180,MATCH(1,薬効分類マスタ!$H$2:$H$180,0)),"") | D28: =IFERROR(INDEX(薬効分類マスタ!$D$2:$D$180,MATCH(1,薬効分類マスタ!$H$2:$H$180,0)),"") | E28: =IFERROR(INDEX(薬効分類マスタ!$E$2:$E$180,MATCH(1,薬効分類マスタ!$H$2:$H$180,0))&"","")
A29: =IFERROR(INDEX(薬効分類マスタ!$A$2:$A$180,MATCH(2,薬効分類マスタ!$H$2:$H$180,0)),"") | B29: =IFERROR(INDEX(薬効分類マスタ!$B$2:$B$180,MATCH(2,薬効分類マスタ!$H$2:$H$180,0)),"") | C29: =IFERROR(INDEX(薬効分類マスタ!$C$2:$C$180,MATCH(2,薬効分類マスタ!$H$2:$H$180,0)),"") | D29: =IFERROR(INDEX(薬効分類マスタ!$D$2:$D$180,MATCH(2,薬効分類マスタ!$H$2:$H$180,0)),"") | E29: =IFERROR(INDEX(薬効分類マスタ!$E$2:$E$180,MATCH(2,薬効分類マスタ!$H$2:$H$180,0))&"","")
A30: =IFERROR(INDEX(薬効分類マスタ!$A$2:$A$180,MATCH(3,薬効分類マスタ!$H$2:$H$180,0)),"") | B30: =IFERROR(INDEX(薬効分類マスタ!$B$2:$B$180,MATCH(3,薬効分類マスタ!$H$2:$H$180,0)),"") | C30: =IFERROR(INDEX(薬効分類マスタ!$C$2:$C$180,MATCH(3,薬効分類マスタ!$H$2:$H$180,0)),"") | D30: =IFERROR(INDEX(薬効分類マスタ!$D$2:$D$180,MATCH(3,薬効分類マスタ!$H$2:$H$180,0)),"") | E30: =IFERROR(INDEX(薬効分類マスタ!$E$2:$E$180,MATCH(3,薬効分類マスタ!$H$2:$H$180,0))&"","")
A31: =IFERROR(INDEX(薬効分類マスタ!$A$2:$A$180,MATCH(4,薬効分類マスタ!$H$2:$H$180,0)),"") | B31: =IFERROR(INDEX(薬効分類マスタ!$B$2:$B$180,MATCH(4,薬効分類マスタ!$H$2:$H$180,0)),"") | C31: =IFERROR(INDEX(薬効分類マスタ!$C$2:$C$180,MATCH(4,薬効分類マスタ!$H$2:$H$180,0)),"") | D31: =IFERROR(INDEX(薬効分類マスタ!$D$2:$D$180,MATCH(4,薬効分類マスタ!$H$2:$H$180,0)),"") | E31: =IFERROR(INDEX(薬効分類マスタ!$E$2:$E$180,MATCH(4,薬効分類マスタ!$H$2:$H$180,0))&"","")
A32: =IFERROR(INDEX(薬効分類マスタ!$A$2:$A$180,MATCH(5,薬効分類マスタ!$H$2:$H$180,0)),"") | B32: =IFERROR(INDEX(薬効分類マスタ!$B$2:$B$180,MATCH(5,薬効分類マスタ!$H$2:$H$180,0)),"") | C32: =IFERROR(INDEX(薬効分類マスタ!$C$2:$C$180,MATCH(5,薬効分類マスタ!$H$2:$H$180,0)),"") | D32: =IFERROR(INDEX(薬効分類マスタ!$D$2:$D$180,MATCH(5,薬効分類マスタ!$H$2:$H$180,0)),"") | E32: =IFERROR(INDEX(薬効分類マスタ!$E$2:$E$180,MATCH(5,薬効分類マスタ!$H$2:$H$180,0))&"","")
A33: =IFERROR(INDEX(薬効分類マスタ!$A$2:$A$180,MATCH(6,薬効分類マスタ!$H$2:$H$180,0)),"") | B33: =IFERROR(INDEX(薬効分類マスタ!$B$2:$B$180,MATCH(6,薬効分類マスタ!$H$2:$H$180,0)),"") | C33: =IFERROR(INDEX(薬効分類マスタ!$C$2:$C$180,MATCH(6,薬効分類マスタ!$H$2:$H$180,0)),"") | D33: =IFERROR(INDEX(薬効分類マスタ!$D$2:$D$180,MATCH(6,薬効分類マスタ!$H$2:$H$180,0)),"") | E33: =IFERROR(INDEX(薬効分類マスタ!$E$2:$E$180,MATCH(6,薬効分類マスタ!$H$2:$H$180,0))&"","")
A34: =IFERROR(INDEX(薬効分類マスタ!$A$2:$A$180,MATCH(7,薬効分類マスタ!$H$2:$H$180,0)),"") | B34: =IFERROR(INDEX(薬効分類マスタ!$B$2:$B$180,MATCH(7,薬効分類マスタ!$H$2:$H$180,0)),"") | C34: =IFERROR(INDEX(薬効分類マスタ!$C$2:$C$180,MATCH(7,薬効分類マスタ!$H$2:$H$180,0)),"") | D34: =IFERROR(INDEX(薬効分類マスタ!$D$2:$D$180,MATCH(7,薬効分類マスタ!$H$2:$H$180,0)),"") | E34: =IFERROR(INDEX(薬効分類マスタ!$E$2:$E$180,MATCH(7,薬効分類マスタ!$H$2:$H$180,0))&"","")
A35: =IFERROR(INDEX(薬効分類マスタ!$A$2:$A$180,MATCH(8,薬効分類マスタ!$H$2:$H$180,0)),"") | B35: =IFERROR(INDEX(薬効分類マスタ!$B$2:$B$180,MATCH(8,薬効分類マスタ!$H$2:$H$180,0)),"") | C35: =IFERROR(INDEX(薬効分類マスタ!$C$2:$C$180,MATCH(8,薬効分類マスタ!$H$2:$H$180,0)),"") | D35: =IFERROR(INDEX(薬効分類マスタ!$D$2:$D$180,MATCH(8,薬効分類マスタ!$H$2:$H$180,0)),"") | E35: =IFERROR(INDEX(薬効分類マスタ!$E$2:$E$180,MATCH(8,薬効分類マスタ!$H$2:$H$180,0))&"","")
A36: =IFERROR(INDEX(薬効分類マスタ!$A$2:$A$180,MATCH(9,薬効分類マスタ!$H$2:$H$180,0)),"") | B36: =IFERROR(INDEX(薬効分類マスタ!$B$2:$B$180,MATCH(9,薬効分類マスタ!$H$2:$H$180,0)),"") | C36: =IFERROR(INDEX(薬効分類マスタ!$C$2:$C$180,MATCH(9,薬効分類マスタ!$H$2:$H$180,0)),"") | D36: =IFERROR(INDEX(薬効分類マスタ!$D$2:$D$180,MATCH(9,薬効分類マスタ!$H$2:$H$180,0)),"") | E36: =IFERROR(INDEX(薬効分類マスタ!$E$2:$E$180,MATCH(9,薬効分類マスタ!$H$2:$H$180,0))&"","")
A37: =IFERROR(INDEX(薬効分類マスタ!$A$2:$A$180,MATCH(10,薬効分類マスタ!$H$2:$H$180,0)),"") | B37: =IFERROR(INDEX(薬効分類マスタ!$B$2:$B$180,MATCH(10,薬効分類マスタ!$H$2:$H$180,0)),"") | C37: =IFERROR(INDEX(薬効分類マスタ!$C$2:$C$180,MATCH(10,薬効分類マスタ!$H$2:$H$180,0)),"") | D37: =IFERROR(INDEX(薬効分類マスタ!$D$2:$D$180,MATCH(10,薬効分類マスタ!$H$2:$H$180,0)),"") | E37: =IFERROR(INDEX(薬効分類マスタ!$E$2:$E$180,MATCH(10,薬効分類マスタ!$H$2:$H$180,0))&"","")
A38: =IFERROR(INDEX(薬効分類マスタ!$A$2:$A$180,MATCH(11,薬効分類マスタ!$H$2:$H$180,0)),"") | B38: =IFERROR(INDEX(薬効分類マスタ!$B$2:$B$180,MATCH(11,薬効分類マスタ!$H$2:$H$180,0)),"") | C38: =IFERROR(INDEX(薬効分類マスタ!$C$2:$C$180,MATCH(11,薬効分類マスタ!$H$2:$H$180,0)),"") | D38: =IFERROR(INDEX(薬効分類マスタ!$D$2:$D$180,MATCH(11,薬効分類マスタ!$H$2:$H$180,0)),"") | E38: =IFERROR(INDEX(薬効分類マスタ!$E$2:$E$180,MATCH(11,薬効分類マスタ!$H$2:$H$180,0))&"","")
A39: =IFERROR(INDEX(薬効分類マスタ!$A$2:$A$180,MATCH(12,薬効分類マスタ!$H$2:$H$180,0)),"") | B39: =IFERROR(INDEX(薬効分類マスタ!$B$2:$B$180,MATCH(12,薬効分類マスタ!$H$2:$H$180,0)),"") | C39: =IFERROR(INDEX(薬効分類マスタ!$C$2:$C$180,MATCH(12,薬効分類マスタ!$H$2:$H$180,0)),"") | D39: =IFERROR(INDEX(薬効分類マスタ!$D$2:$D$180,MATCH(12,薬効分類マスタ!$H$2:$H$180,0)),"") | E39: =IFERROR(INDEX(薬効分類マスタ!$E$2:$E$180,MATCH(12,薬効分類マスタ!$H$2:$H$180,0))&"","")
A40: =IFERROR(INDEX(薬効分類マスタ!$A$2:$A$180,MATCH(13,薬効分類マスタ!$H$2:$H$180,0)),"") | B40: =IFERROR(INDEX(薬効分類マスタ!$B$2:$B$180,MATCH(13,薬効分類マスタ!$H$2:$H$180,0)),"") | C40: =IFERROR(INDEX(薬効分類マスタ!$C$2:$C$180,MATCH(13,薬効分類マスタ!$H$2:$H$180,0)),"") | D40: =IFERROR(INDEX(薬効分類マスタ!$D$2:$D$180,MATCH(13,薬効分類マスタ!$H$2:$H$180,0)),"") | E40: =IFERROR(INDEX(薬効分類マスタ!$E$2:$E$180,MATCH(13,薬効分類マスタ!$H$2:$H$180,0))&"","")
A41: =IFERROR(INDEX(薬効分類マスタ!$A$2:$A$180,MATCH(14,薬効分類マスタ!$H$2:$H$180,0)),"") | B41: =IFERROR(INDEX(薬効分類マスタ!$B$2:$B$180,MATCH(14,薬効分類マスタ!$H$2:$H$180,0)),"") | C41: =IFERROR(INDEX(薬効分類マスタ!$C$2:$C$180,MATCH(14,薬効分類マスタ!$H$2:$H$180,0)),"") | D41: =IFERROR(INDEX(薬効分類マスタ!$D$2:$D$180,MATCH(14,薬効分類マスタ!$H$2:$H$180,0)),"") | E41: =IFERROR(INDEX(薬効分類マスタ!$E$2:$E$180,MATCH(14,薬効分類マスタ!$H$2:$H$180,0))&"","")
A42: =IFERROR(INDEX(薬効分類マスタ!$A$2:$A$180,MATCH(15,薬効分類マスタ!$H$2:$H$180,0)),"") | B42: =IFERROR(INDEX(薬効分類マスタ!$B$2:$B$180,MATCH(15,薬効分類マスタ!$H$2:$H$180,0)),"") | C42: =IFERROR(INDEX(薬効分類マスタ!$C$2:$C$180,MATCH(15,薬効分類マスタ!$H$2:$H$180,0)),"") | D42: =IFERROR(INDEX(薬効分類マスタ!$D$2:$D$180,MATCH(15,薬効分類マスタ!$H$2:$H$180,0)),"") | E42: =IFERROR(INDEX(薬効分類マスタ!$E$2:$E$180,MATCH(15,薬効分類マスタ!$H$2:$H$180,0))&"","")
A43: =IF($B$25="","",IF(MAX(薬効分類マスタ!$H$2:$H$180)=0,"該当する薬効分類がありません",IF(MAX(薬効分類マスタ!$H$2:$H$180)>15,"※ "&MAX(薬効分類マスタ!$H$2:$H$180)&"件該当しました（先頭15件を表示）","")))
A46: ③ 薬効分類コードから医薬品を一覧
A47: 黄色いセルに薬効分類コード3桁（例: 114）を入力すると、該当する医薬品（内用薬・外用薬）を最大30件まで表示します。全件は「医薬品マスタ」シートで「薬効分類コード」を絞り込んでください。
A49: 薬効分類コード（3桁）
A51: 区分／成分名 | B51: 品名 | C51: 規格 | D51: 薬価 | E51: 対象区分
A52: =IFERROR(INDEX(医薬品マスタ!$A$2:$A$8936,MATCH(1,医薬品マスタ!$P$2:$P$8936,0))&"／"&INDEX(医薬品マスタ!$E$2:$E$8936,MATCH(1,医薬品マスタ!$P$2:$P$8936,0)),"") | B52: =IFERROR(INDEX(医薬品マスタ!$G$2:$G$8936,MATCH(1,医薬品マスタ!$P$2:$P$8936,0)),"") | C52: =IFERROR(INDEX(医薬品マスタ!$F$2:$F$8936,MATCH(1,医薬品マスタ!$P$2:$P$8936,0)),"") | D52: =IFERROR(INDEX(医薬品マスタ!$I$2:$I$8936,MATCH(1,医薬品マスタ!$P$2:$P$8936,0)),"") | E52: =IFERROR(INDEX(医薬品マスタ!$K$2:$K$8936,MATCH(1,医薬品マスタ!$P$2:$P$8936,0)),"")
A53: =IFERROR(INDEX(医薬品マスタ!$A$2:$A$8936,MATCH(2,医薬品マスタ!$P$2:$P$8936,0))&"／"&INDEX(医薬品マスタ!$E$2:$E$8936,MATCH(2,医薬品マスタ!$P$2:$P$8936,0)),"") | B53: =IFERROR(INDEX(医薬品マスタ!$G$2:$G$8936,MATCH(2,医薬品マスタ!$P$2:$P$8936,0)),"") | C53: =IFERROR(INDEX(医薬品マスタ!$F$2:$F$8936,MATCH(2,医薬品マスタ!$P$2:$P$8936,0)),"") | D53: =IFERROR(INDEX(医薬品マスタ!$I$2:$I$8936,MATCH(2,医薬品マスタ!$P$2:$P$8936,0)),"") | E53: =IFERROR(INDEX(医薬品マスタ!$K$2:$K$8936,MATCH(2,医薬品マスタ!$P$2:$P$8936,0)),"")
...

Sheet 薬効分類マスタ
A1: 薬効分類コード | B1: 薬効分類名 | C1: 内用薬の件数 | D1: 外用薬の件数 | E1: 対象区分 | F1: 有効期限(年) | G1: 検索一致(計算) | H1: 検索順位(計算) | J1: 【使い方】黄色いセルが設定欄です。「対象区分」に 抗菌薬 / 解熱鎮痛薬 / 麻薬 を選ぶと、その薬効分類の医薬品が在庫管理アプリの薬剤マスタとして取り込まれます（空欄の分類は取り込まれません）。
A2: 111 | B2: 全身麻酔剤 | C2: =COUNTIFS(医薬品マスタ!$C$2:$C$8936,$A2,医薬品マスタ!$A$2:$A$8936,"内用薬") -> 0 | D2: =COUNTIFS(医薬品マスタ!$C$2:$C$8936,$A2,医薬品マスタ!$A$2:$A$8936,"外用薬") -> 11 | G2: =IF(検索!$B$25="",0,IF(OR(ISNUMBER(SEARCH(検索!$B$25,$A2&"")),ISNUMBER(SEARCH(検索!$B$25,$B2))),1,0)) -> 0 | H2: =N(H1)+G2 -> 0 | J2: 「有効期限(年)」は製造からの有効期限で、薬効分類ごとの標準値です。個別の医薬品だけ変えたい場合は「医薬品マスタ」シートの「個別設定(年)」に入力します。
A3: 112 | B3: 催眠鎮静剤,抗不安剤 | C3: =COUNTIFS(医薬品マスタ!$C$2:$C$8936,$A3,医薬品マスタ!$A$2:$A$8936,"内用薬") -> 150 | D3: =COUNTIFS(医薬品マスタ!$C$2:$C$8936,$A3,医薬品マスタ!$A$2:$A$8936,"外用薬") -> 14 | G3: =IF(検索!$B$25="",0,IF(OR(ISNUMBER(SEARCH(検索!$B$25,$A3&"")),ISNUMBER(SEARCH(検索!$B$25,$B3))),1,0)) -> 0 | H3: =N(H2)+G3 -> 0 | J3: ※ 初期設定の分類と有効期限(3年)は仮の値です。必ず確認してから使用してください。
A4: 113 | B4: 抗てんかん剤 | C4: =COUNTIFS(医薬品マスタ!$C$2:$C$8936,$A4,医薬品マスタ!$A$2:$A$8936,"内用薬") -> 185 | D4: =COUNTIFS(医薬品マスタ!$C$2:$C$8936,$A4,医薬品マスタ!$A$2:$A$8936,"外用薬") -> 7 | G4: =IF(検索!$B$25="",0,IF(OR(ISNUMBER(SEARCH(検索!$B$25,$A4&"")),ISNUMBER(SEARCH(検索!$B$25,$B4))),1,0)) -> 0 | H4: =N(H3)+G4 -> 0
A5: 114 | B5: 解熱鎮痛消炎剤 | C5: =COUNTIFS(医薬品マスタ!$C$2:$C$8936,$A5,医薬品マスタ!$A$2:$A$8936,"内用薬") -> 139 | D5: =COUNTIFS(医薬品マスタ!$C$2:$C$8936,$A5,医薬品マスタ!$A$2:$A$8936,"外用薬") -> 31 | E5: 解熱鎮痛薬 | F5: 3 | G5: =IF(検索!$B$25="",0,IF(OR(ISNUMBER(SEARCH(検索!$B$25,$A5&"")),ISNUMBER(SEARCH(検索!$B$25,$B5))),1,0)) -> 0 | H5: =N(H4)+G5 -> 0
A6: 115 | B6: 興奮剤、覚せい剤 | C6: =COUNTIFS(医薬品マスタ!$C$2:$C$8936,$A6,医薬品マスタ!$A$2:$A$8936,"内用薬") -> 0 | D6: =COUNTIFS(医薬品マスタ!$C$2:$C$8936,$A6,医薬品マスタ!$A$2:$A$8936,"外用薬") -> 0 | G6: =IF(検索!$B$25="",0,IF(OR(ISNUMBER(SEARCH(検索!$B$25,$A6&"")),ISNUMBER(SEARCH(検索!$B$25,$B6))),1,0)) -> 0 | H6: =N(H5)+G6 -> 0
A7: 116 | B7: 抗パーキンソン剤 | C7: =COUNTIFS(医薬品マスタ!$C$2:$C$8936,$A7,医薬品マスタ!$A$2:$A$8936,"内用薬") -> 134 | D7: =COUNTIFS(医薬品マスタ!$C$2:$C$8936,$A7,医薬品マスタ!$A$2:$A$8936,"外用薬") -> 10 | G7: =IF(検索!$B$25="",0,IF(OR(ISNUMBER(SEARCH(検索!$B$25,$A7&"")),ISNUMBER(SEARCH(検索!$B$25,$B7))),1,0)) -> 0 | H7: =N(H6)+G7 -> 0
A8: 117 | B8: 精神神経用剤 | C8: =COUNTIFS(医薬品マスタ!$C$2:$C$8936,$A8,医薬品マスタ!$A$2:$A$8936,"内用薬") -> 574 | D8: =COUNTIFS(医薬品マスタ!$C$2:$C$8936,$A8,医薬品マスタ!$A$2:$A$8936,"外用薬") -> 3 | G8: =IF(検索!$B$25="",0,IF(OR(ISNUMBER(SEARCH(検索!$B$25,$A8&"")),ISNUMBER(SEARCH(検索!$B$25,$B8))),1,0)) -> 0 | H8: =N(H7)+G8 -> 0
A9: 118 | B9: 総合感冒剤 | C9: =COUNTIFS(医薬品マスタ!$C$2:$C$8936,$A9,医薬品マスタ!$A$2:$A$8936,"内用薬") -> 9 | D9: =COUNTIFS(医薬品マスタ!$C$2:$C$8936,$A9,医薬品マスタ!$A$2:$A$8936,"外用薬") -> 0 | G9: =IF(検索!$B$25="",0,IF(OR(ISNUMBER(SEARCH(検索!$B$25,$A9&"")),ISNUMBER(SEARCH(検索!$B$25,$B9))),1,0)) -> 0 | H9: =N(H8)+G9 -> 0
A10: 119 | B10: その他の中枢神経系用薬 | C10: =COUNTIFS(医薬品マスタ!$C$2:$C$8936,$A10,医薬品マスタ!$A$2:$A$8936,"内用薬") -> 337 | D10: =COUNTIFS(医薬品マスタ!$C$2:$C$8936,$A10,医薬品マスタ!$A$2:$A$8936,"外用薬") -> 52 | G10: =IF(検索!$B$25="",0,IF(OR(ISNUMBER(SEARCH(検索!$B$25,$A10&"")),ISNUMBER(SEARCH(検索!$B$25,$B10))),1,0)) -> 0 | H10: =N(H9)+G10 -> 0
A11: 121 | B11: 局所麻酔剤 | C11: =COUNTIFS(医薬品マスタ!$C$2:$C$8936,$A11,医薬品マスタ!$A$2:$A$8936,"内用薬") -> 4 | D11: =COUNTIFS(医薬品マスタ!$C$2:$C$8936,$A11,医薬品マスタ!$A$2:$A$8936,"外用薬") -> 12 | G11: =IF(検索!$B$25="",0,IF(OR(ISNUMBER(SEARCH(検索!$B$25,$A11&"")),ISNUMBER(SEARCH(検索!$B$25,$B11))),1,0)) -> 0 | H11: =N(H10)+G11 -> 0
A12: 122 | B12: 骨格筋弛緩剤 | C12: =COUNTIFS(医薬品マスタ!$C$2:$C$8936,$A12,医薬品マスタ!$A$2:$A$8936,"内用薬") -> 6 | D12: =COUNTIFS(医薬品マスタ!$C$2:$C$8936,$A12,医薬品マスタ!$A$2:$A$8936,"外用薬") -> 0 | G12: =IF(検索!$B$25="",0,IF(OR(ISNUMBER(SEARCH(検索!$B$25,$A12&"")),ISNUMBER(SEARCH(検索!$B$25,$B12))),1,0)) -> 0 | H12: =N(H11)+G12 -> 0
A13: 123 | B13: 自律神経剤 | C13: =COUNTIFS(医薬品マスタ!$C$2:$C$8936,$A13,医薬品マスタ!$A$2:$A$8936,"内用薬") -> 14 | D13: =COUNTIFS(医薬品マスタ!$C$2:$C$8936,$A13,医薬品マスタ!$A$2:$A$8936,"外用薬") -> 0 | G13: =IF(検索!$B$25="",0,IF(OR(ISNUMBER(SEARCH(検索!$B$25,$A13&"")),ISNUMBER(SEARCH(検索!$B$25,$B13))),1,0)) -> 0 | H13: =N(H12)+G13 -> 0
A14: 124 | B14: 鎮けい剤 | C14: =COUNTIFS(医薬品マスタ!$C$2:$C$8936,$A14,医薬品マスタ!$A$2:$A$8936,"内用薬") -> 22 | D14: =COUNTIFS(医薬品マスタ!$C$2:$C$8936,$A14,医薬品マスタ!$A$2:$A$8936,"外用薬") -> 0 | G14: =IF(検索!$B$25="",0,IF(OR(ISNUMBER(SEARCH(検索!$B$25,$A14&"")),ISNUMBER(SEARCH(検索!$B$25,$B14))),1,0)) -> 0 | H14: =N(H13)+G14 -> 0
A15: 125 | B15: 発汗剤,止汗剤 | C15: =COUNTIFS(医薬品マスタ!$C$2:$C$8936,$A15,医薬品マスタ!$A$2:$A$8936,"内用薬") -> 0 | D15: =COUNTIFS(医薬品マスタ!$C$2:$C$8936,$A15,医薬品マスタ!$A$2:$A$8936,"外用薬") -> 3 | G15: =IF(検索!$B$25="",0,IF(OR(ISNUMBER(SEARCH(検索!$B$25,$A15&"")),ISNUMBER(SEARCH(検索!$B$25,$B15))),1,0)) -> 0 | H15: =N(H14)+G15 -> 0
A16: 129 | B16: その他の末梢神経系用薬 | C16: =COUNTIFS(医薬品マスタ!$C$2:$C$8936,$A16,医薬品マスタ!$A$2:$A$8936,"内用薬") -> 2 | D16: =COUNTIFS(医薬品マスタ!$C$2:$C$8936,$A16,医薬品マスタ!$A$2:$A$8936,"外用薬") -> 0 | G16: =IF(検索!$B$25="",0,IF(OR(ISNUMBER(SEARCH(検索!$B$25,$A16&"")),ISNUMBER(SEARCH(検索!$B$25,$B16))),1,0)) -> 0 | H16: =N(H15)+G16 -> 0
A17: 131 | B17: 眼科用剤 | C17: =COUNTIFS(医薬品マスタ!$C$2:$C$8936,$A17,医薬品マスタ!$A$2:$A$8936,"内用薬") -> 1 | D17: =COUNTIFS(医薬品マスタ!$C$2:$C$8936,$A17,医薬品マスタ!$A$2:$A$8936,"外用薬") -> 355 | G17: =IF(検索!$B$25="",0,IF(OR(ISNUMBER(SEARCH(検索!$B$25,$A17&"")),ISNUMBER(SEARCH(検索!$B$25,$B17))),1,0)) -> 0 | H17: =N(H16)+G17 -> 0
... A124: 590 | B124: その他の生薬及び漢方処方に基づく医薬品 | C124: =COUNTIFS(医薬品マスタ!$C$2:$C$8936,$A124,医薬品マスタ!$A$2:$A$8936,"内用薬") -> 9 | D124: =COUNTIFS(医薬品マスタ!$C$2:$C$8936,$A124,医薬品マスタ!$A$2:$A$8936,"外用薬") -> 0 | G124: =IF(検索!$B$25="",0,IF(OR(ISNUMBER(SEARCH(検索!$B$25,$A124&"")),ISNUMBER(SEARCH(検索!$B$25,$B124))),1,0)) -> 0 | H124: =N(H123)+G124 -> 0
A125: 611 | B125: 主としてグラム陽性菌に作用するもの | C125: =COUNTIFS(医薬品マスタ!$C$2:$C$8936,$A125,医薬品マスタ!$A$2:$A$8936,"内用薬") -> 9 | D125: =COUNTIFS(医薬品マスタ!$C$2:$C$8936,$A125,医薬品マスタ!$A$2:$A$8936,"外用薬") -> 2 | E125: 抗菌薬 | F125: 3 | G125: =IF(検索!$B$25="",0,IF(OR(ISNUMBER(SEARCH(検索!$B$25,$A125&"")),ISNUMBER(SEARCH(検索!$B$25,$B125))),1,0)) -> 0 | H125: =N(H124)+G125 -> 0
A126: 612 | B126: 主としてグラム陰性菌に作用するもの | C126: =COUNTIFS(医薬品マスタ!$C$2:$C$8936,$A126,医薬品マスタ!$A$2:$A$8936,"内用薬") -> 4 | D126: =COUNTIFS(医薬品マスタ!$C$2:$C$8936,$A126,医薬品マスタ!$A$2:$A$8936,"外用薬") -> 1 | E126: 抗菌薬 | F126: 3 | G126: =IF(検索!$B$25="",0,IF(OR(ISNUMBER(SEARCH(検索!$B$25,$A126&"")),ISNUMBER(SEARCH(検索!$B$25,$B126))),1,0)) -> 0 | H126: =N(H125)+G126 -> 0
A127: 613 | B127: 主としてグラム陽性・陰性菌に作用するもの | C127: =COUNTIFS(医薬品マスタ!$C$2:$C$8936,$A127,医薬品マスタ!$A$2:$A$8936,"内用薬") -> 110 | D127: =COUNTIFS(医薬品マスタ!$C$2:$C$8936,$A127,医薬品マスタ!$A$2:$A$8936,"外用薬") -> 2 | E127: 抗菌薬 | F127: 3 | G127: =IF(検索!$B$25="",0,IF(OR(ISNUMBER(SEARCH(検索!$B$25,$A127&"")),ISNUMBER(SEARCH(検索!$B$25,$B127))),1,0)) -> 0 | H127: =N(H126)+G127 -> 0
A128: 614 | B128: 主としてグラム陽性菌、マイコプラズマに作用するもの | C128: =COUNTIFS(医薬品マスタ!$C$2:$C$8936,$A128,医薬品マスタ!$A$2:$A$8936,"内用薬") -> 42 | D128: =COUNTIFS(医薬品マスタ!$C$2:$C$8936,$A128,医薬品マスタ!$A$2:$A$8936,"外用薬") -> 0 | E128: 抗菌薬 | F128: 3 | G128: =IF(検索!$B$25="",0,IF(OR(ISNUMBER(SEARCH(検索!$B$25,$A128&"")),ISNUMBER(SEARCH(検索!$B$25,$B128))),1,0)) -> 0 | H128: =N(H127)+G128 -> 0
A129: 615 | B129: 主としてグラム陽性・陰性菌、リケッチア、クラミジアに作用するもの | C129: =COUNTIFS(医薬品マスタ!$C$2:$C$8936,$A129,医薬品マスタ!$A$2:$A$8936,"内用薬") -> 16 | D129: =COUNTIFS(医薬品マスタ!$C$2:$C$8936,$A129,医薬品マスタ!$A$2:$A$8936,"外用薬") -> 0 | E129: 抗菌薬 | F129: 3 | G129: =IF(検索!$B$25="",0,IF(OR(ISNUMBER(SEARCH(検索!$B$25,$A129&"")),ISNUMBER(SEARCH(検索!$B$25,$B129))),1,0)) -> 0 | H129: =N(H128)+G129 -> 0
A130: 616 | B130: 主として抗酸菌に作用するもの | C130: =COUNTIFS(医薬品マスタ!$C$2:$C$8936,$A130,医薬品マスタ!$A$2:$A$8936,"内用薬") -> 4 | D130: =COUNTIFS(医薬品マスタ!$C$2:$C$8936,$A130,医薬品マスタ!$A$2:$A$8936,"外用薬") -> 1 | G130: =IF(検索!$B$25="",0,IF(OR(ISNUMBER(SEARCH(検索!$B$25,$A130&"")),ISNUMBER(SEARCH(検索!$B$25,$B130))),1,0)) -> 0 | H130: =N(H129)+G130 -> 0
A131: 617 | B131: 主としてカビに作用するもの | C131: =COUNTIFS(医薬品マスタ!$C$2:$C$8936,$A131,医薬品マスタ!$A$2:$A$8936,"内用薬") -> 23 | D131: =COUNTIFS(医薬品マスタ!$C$2:$C$8936,$A131,医薬品マスタ!$A$2:$A$8936,"外用薬") -> 0 | G131: =IF(検索!$B$25="",0,IF(OR(ISNUMBER(SEARCH(検索!$B$25,$A131&"")),ISNUMBER(SEARCH(検索!$B$25,$B131))),1,0)) -> 0 | H131: =N(H130)+G131 -> 0
A132: 619 | B132: その他の抗生物質製剤(複合抗生物質製剤を含む。) | C132: =COUNTIFS(医薬品マスタ!$C$2:$C$8936,$A132,医薬品マスタ!$A$2:$A$8936,"内用薬") -> 5 | D132: =COUNTIFS(医薬品マスタ!$C$2:$C$8936,$A132,医薬品マスタ!$A$2:$A$8936,"外用薬") -> 0 | E132: 抗菌薬 | F132: 3 | G132: =IF(検索!$B$25="",0,IF(OR(ISNUMBER(SEARCH(検索!$B$25,$A132&"")),ISNUMBER(SEARCH(検索!$B$25,$B132))),1,0)) -> 0 | H132: =N(H131)+G132 -> 0
A133: 621 | B133: サルファ剤 | C133: =COUNTIFS(医薬品マスタ!$C$2:$C$8936,$A133,医薬品マスタ!$A$2:$A$8936,"内用薬") -> 9 | D133: =COUNTIFS(医薬品マスタ!$C$2:$C$8936,$A133,医薬品マスタ!$A$2:$A$8936,"外用薬") -> 1 | E133: 抗菌薬 | F133: 3 | G133: =IF(検索!$B$25="",0,IF(OR(ISNUMBER(SEARCH(検索!$B$25,$A133&"")),ISNUMBER(SEARCH(検索!$B$25,$B133))),1,0)) -> 0 | H133: =N(H132)+G133 -> 0
A134: 622 | B134: 抗結核剤 | C134: =COUNTIFS(医薬品マスタ!$C$2:$C$8936,$A134,医薬品マスタ!$A$2:$A$8936,"内用薬") -> 13 | D134: =COUNTIFS(医薬品マスタ!$C$2:$C$8936,$A134,医薬品マスタ!$A$2:$A$8936,"外用薬") -> 0 | G134: =IF(検索!$B$25="",0,IF(OR(ISNUMBER(SEARCH(検索!$B$25,$A134&"")),ISNUMBER(SEARCH(検索!$B$25,$B134))),1,0)) -> 0 | H134: =N(H133)+G134 -> 0
A135: 623 | B135: 抗ハンセン病剤 | C135: =COUNTIFS(医薬品マスタ!$C$2:$C$8936,$A135,医薬品マスタ!$A$2:$A$8936,"内用薬") -> 1 | D135: =COUNTIFS(医薬品マスタ!$C$2:$C$8936,$A135,医薬品マスタ!$A$2:$A$8936,"外用薬") -> 0 | G135: =IF(検索!$B$25="",0,IF(OR(ISNUMBER(SEARCH(検索!$B$25,$A135&"")),ISNUMBER(SEARCH(検索!$B$25,$B135))),1,0)) -> 0 | H135: =N(H134)+G135 -> 0
A136: 624 | B136: 合成抗菌剤 | C136: =COUNTIFS(医薬品マスタ!$C$2:$C$8936,$A136,医薬品マスタ!$A$2:$A$8936,"内用薬") -> 61 | D136: =COUNTIFS(医薬品マスタ!$C$2:$C$8936,$A136,医薬品マスタ!$A$2:$A$8936,"外用薬") -> 0 | E136: 抗菌薬 | F136: 3 | G136: =IF(検索!$B$25="",0,IF(OR(ISNUMBER(SEARCH(検索!$B$25,$A136&"")),ISNUMBER(SEARCH(検索!$B$25,$B136))),1,0)) -> 0 | H136: =N(H135)+G136 -> 0
A137: 625 | B137: 抗ウイルス剤 | C137: =COUNTIFS(医薬品マスタ!$C$2:$C$8936,$A137,医薬品マスタ!$A$2:$A$8936,"内用薬") -> 118 | D137: =COUNTIFS(医薬品マスタ!$C$2:$C$8936,$A137,医薬品マスタ!$A$2:$A$8936,"外用薬") -> 11 | G137: =IF(検索!$B$25="",0,IF(OR(ISNUMBER(SEARCH(検索!$B$25,$A137&"")),ISNUMBER(SEARCH(検索!$B$25,$B137))),1,0)) -> 0 | H137: =N(H136)+G137 -> 0
A138: 629 | B138: その他の化学療法剤 | C138: =COUNTIFS(医薬品マスタ!$C$2:$C$8936,$A138,医薬品マスタ!$A$2:$A$8936,"内用薬") -> 39 | D138: =COUNTIFS(医薬品マスタ!$C$2:$C$8936,$A138,医薬品マスタ!$A$2:$A$8936,"外用薬") -> 7 | G138: =IF(検索!$B$25="",0,IF(OR(ISNUMBER(SEARCH(検索!$B$25,$A138&"")),ISNUMBER(SEARCH(検索!$B$25,$B138))),1,0)) -> 0 | H138: =N(H137)+G138 -> 0
A139: 631 | B139: ワクチン類 | C139: =COUNTIFS(医薬品マスタ!$C$2:$C$8936,$A139,医薬品マスタ!$A$2:$A$8936,"内用薬") -> 0 | D139: =COUNTIFS(医薬品マスタ!$C$2:$C$8936,$A139,医薬品マスタ!$A$2:$A$8936,"外用薬") -> 0 | G139: =IF(検索!$B$25="",0,IF(OR(ISNUMBER(SEARCH(検索!$B$25,$A139&"")),ISNUMBER(SEARCH(検索!$B$25,$B139))),1,0)) -> 0 | H139: =N(H138)+G139 -> 0
A140: 632 | B140: 毒素及びトキソイド類 | C140: =COUNTIFS(医薬品マスタ!$C$2:$C$8936,$A140,医薬品マスタ!$A$2:$A$8936,"内用薬") -> 0 | D140: =COUNTIFS(医薬品マスタ!$C$2:$C$8936,$A140,医薬品マスタ!$A$2:$A$8936,"外用薬") -> 0 | G140: =IF(検索!$B$25="",0,IF(OR(ISNUMBER(SEARCH(検索!$B$25,$A140&"")),ISNUMBER(SEARCH(検索!$B$25,$B140))),1,0)) -> 0 | H140: =N(H139)+G140 -> 0
A141: 633 | B141: 抗毒素類及び抗レプトスピラ血清類 | C141: =COUNTIFS(医薬品マスタ!$C$2:$C$8936,$A141,医薬品マスタ!$A$2:$A$8936,"内用薬") -> 0 | D141: =COUNTIFS(医薬品マスタ!$C$2:$C$8936,$A141,医薬品マスタ!$A$2:$A$8936,"外用薬") -> 0 | G141: =IF(検索!$B$25="",0,IF(OR(ISNUMBER(SEARCH(検索!$B$25,$A141&"")),ISNUMBER(SEARCH(検索!$B$25,$B141))),1,0)) -> 0 | H141: =N(H140)+G141 -> 0
A142: 634 | B142: 血液製剤類 | C142: =COUNTIFS(医薬品マスタ!$C$2:$C$8936,$A142,医薬品マスタ!$A$2:$A$8936,"内用薬") -> 0 | D142: =COUNTIFS(医薬品マスタ!$C$2:$C$8936,$A142,医薬品マスタ!$A$2:$A$8936,"外用薬") -> 12 | G142: =IF(検索!$B$25="",0,IF(OR(ISNUMBER(SEARCH(検索!$B$25,$A142&"")),ISNUMBER(SEARCH(検索!$B$25,$B142))),1,0)) -> 0 | H142: =N(H141)+G142 -> 0
A143: 635 | B143: 生物学的試験用製剤類 | C143: =COUNTIFS(医薬品マスタ!$C$2:$C$8936,$A143,医薬品マスタ!$A$2:$A$8936,"内用薬") -> 0 | D143: =COUNTIFS(医薬品マスタ!$C$2:$C$8936,$A143,医薬品マスタ!$A$2:$A$8936,"外用薬") -> 0 | G143: =IF(検索!$B$25="",0,IF(OR(ISNUMBER(SEARCH(検索!$B$25,$A143&"")),ISNUMBER(SEARCH(検索!$B$25,$B143))),1,0)) -> 0 | H143: =N(H142)+G143 -> 0
A144: 636 | B144: 混合生物学的製剤 | C144: =COUNTIFS(医薬品マスタ!$C$2:$C$8936,$A144,医薬品マスタ!$A$2:$A$8936,"内用薬") -> 0 | D144: =COUNTIFS(医薬品マスタ!$C$2:$C$8936,$A144,医薬品マスタ!$A$2:$A$8936,"外用薬") -> 0 | G144: =IF(検索!$B$25="",0,IF(OR(ISNUMBER(SEARCH(検索!$B$25,$A144&"")),ISNUMBER(SEARCH(検索!$B$25,$B144))),1,0)) -> 0 | H144: =N(H143)+G144 -> 0
A145: 639 | B145: その他の生物学的製剤 | C145: =COUNTIFS(医薬品マスタ!$C$2:$C$8936,$A145,医薬品マスタ!$A$2:$A$8936,"内用薬") -> 0 | D145: =COUNTIFS(医薬品マスタ!$C$2:$C$8936,$A145,医薬品マスタ!$A$2:$A$8936,"外用薬") -> 2 | G145: =IF(検索!$B$25="",0,IF(OR(ISNUMBER(SEARCH(検索!$B$25,$A145&"")),ISNUMBER(SEARCH(検索!$B$25,$B145))),1,0)) -> 0 | H145: =N(H144)+G145 -> 0
A146: 641 | B146: 抗原虫剤 | C146: =COUNTIFS(医薬品マスタ!$C$2:$C$8936,$A146,医薬品マスタ!$A$2:$A$8936,"内用薬") -> 13 | D146: =COUNTIFS(医薬品マスタ!$C$2:$C$8936,$A146,医薬品マスタ!$A$2:$A$8936,"外用薬") -> 0 | G146: =IF(検索!$B$25="",0,IF(OR(ISNUMBER(SEARCH(検索!$B$25,$A146&"")),ISNUMBER(SEARCH(検索!$B$25,$B146))),1,0)) -> 0 | H146: =N(H145)+G146 -> 0
...

Sheet 医薬品マスタ
A1: 区分 | B1: 薬価基準収載医薬品コード | C1: 薬効分類コード | D1: 薬効分類名 | E1: 成分名 | F1: 規格 | G1: 品名 | H1: メーカー名 | I1: 薬価 | J1: 先発/後発 | K1: 対象区分 | L1: 個別設定(年) | M1: 有効期限(年) | N1: 品名(検索用・半角) | O1: 成分名(検索用・半角) | P1: 一覧用(計算)
A2: 内用薬 | B2: 1121001X1018 | C2: 112 | D2: =IFERROR(VLOOKUP($C2,薬効分類マスタ!$A$2:$B$180,2,FALSE()),"未登録") -> 催眠鎮静剤,抗不安剤 | E2: ブロモバレリル尿素 | F2: １ｇ | G2: ブロモバレリル尿素 | I2: 7.5 | K2: =IFERROR(IF(VLOOKUP($C2,薬効分類マスタ!$A$2:$E$180,5,FALSE())=0,"",VLOOKUP($C2,薬効分類マスタ!$A$2:$E$180,5,FALSE())),"") | M2: =IF($K2="","",IF($L2<>"",$L2,VLOOKUP($C2,薬効分類マスタ!$A$2:$F$180,6,FALSE()))) | N2: =ASC(G2) -> ﾌﾞﾛﾓﾊﾞﾚﾘﾙ尿素 | O2: =ASC(E2) -> ﾌﾞﾛﾓﾊﾞﾚﾘﾙ尿素 | P2: =N(P1)+IF($C2=検索!$B$49,1,0) -> 0
A3: 内用薬 | B3: 1123001X1012 | C3: 112 | D3: =IFERROR(VLOOKUP($C3,薬効分類マスタ!$A$2:$B$180,2,FALSE()),"未登録") -> 催眠鎮静剤,抗不安剤 | E3: 抱水クロラール | F3: １ｇ | G3: 抱水クロラール | I3: 36.9 | K3: =IFERROR(IF(VLOOKUP($C3,薬効分類マスタ!$A$2:$E$180,5,FALSE())=0,"",VLOOKUP($C3,薬効分類マスタ!$A$2:$E$180,5,FALSE())),"") | M3: =IF($K3="","",IF($L3<>"",$L3,VLOOKUP($C3,薬効分類マスタ!$A$2:$F$180,6,FALSE()))) | N3: =ASC(G3) -> 抱水ｸﾛﾗｰﾙ | O3: =ASC(E3) -> 抱水ｸﾛﾗｰﾙ | P3: =N(P2)+IF($C3=検索!$B$49,1,0) -> 0
A4: 内用薬 | B4: 1124001B1039 | C4: 112 | D4: =IFERROR(VLOOKUP($C4,薬効分類マスタ!$A$2:$B$180,2,FALSE()),"未登録") -> 催眠鎮静剤,抗不安剤 | E4: エスタゾラム | F4: １％１ｇ | G4: ユーロジン散１％ | H4: Ｔ’ｓ製薬 | I4: 36 | J4: 先発品 | K4: =IFERROR(IF(VLOOKUP($C4,薬効分類マスタ!$A$2:$E$180,5,FALSE())=0,"",VLOOKUP($C4,薬効分類マスタ!$A$2:$E$180,5,FALSE())),"") | M4: =IF($K4="","",IF($L4<>"",$L4,VLOOKUP($C4,薬効分類マスタ!$A$2:$F$180,6,FALSE()))) | N4: =ASC(G4) -> ﾕｰﾛｼﾞﾝ散1% | O4: =ASC(E4) -> ｴｽﾀｿﾞﾗﾑ | P4: =N(P3)+IF($C4=検索!$B$49,1,0) -> 0
A5: 内用薬 | B5: 1124001F1022 | C5: 112 | D5: =IFERROR(VLOOKUP($C5,薬効分類マスタ!$A$2:$B$180,2,FALSE()),"未登録") -> 催眠鎮静剤,抗不安剤 | E5: エスタゾラム | F5: １ｍｇ１錠 | G5: ユーロジン１ｍｇ錠 | H5: Ｔ’ｓ製薬 | I5: 6.3 | J5: 先発品 | K5: =IFERROR(IF(VLOOKUP($C5,薬効分類マスタ!$A$2:$E$180,5,FALSE())=0,"",VLOOKUP($C5,薬効分類マスタ!$A$2:$E$180,5,FALSE())),"") | M5: =IF($K5="","",IF($L5<>"",$L5,VLOOKUP($C5,薬効分類マスタ!$A$2:$F$180,6,FALSE()))) | N5: =ASC(G5) -> ﾕｰﾛｼﾞﾝ1mg錠 | O5: =ASC(E5) -> ｴｽﾀｿﾞﾗﾑ | P5: =N(P4)+IF($C5=検索!$B$49,1,0) -> 0
A6: 内用薬 | B6: 1124001F1030 | C6: 112 | D6: =IFERROR(VLOOKUP($C6,薬効分類マスタ!$A$2:$B$180,2,FALSE()),"未登録") -> 催眠鎮静剤,抗不安剤 | E6: エスタゾラム | F6: １ｍｇ１錠 | G6: エスタゾラム錠１ｍｇ「アメル」 | H6: 共和薬品工業 | I6: 6.3 | J6: 後発品 | K6: =IFERROR(IF(VLOOKUP($C6,薬効分類マスタ!$A$2:$E$180,5,FALSE())=0,"",VLOOKUP($C6,薬効分類マスタ!$A$2:$E$180,5,FALSE())),"") | M6: =IF($K6="","",IF($L6<>"",$L6,VLOOKUP($C6,薬効分類マスタ!$A$2:$F$180,6,FALSE()))) | N6: =ASC(G6) -> ｴｽﾀｿﾞﾗﾑ錠1mg｢ｱﾒﾙ｣ | O6: =ASC(E6) -> ｴｽﾀｿﾞﾗﾑ | P6: =N(P5)+IF($C6=検索!$B$49,1,0) -> 0
A7: 内用薬 | B7: 1124001F2029 | C7: 112 | D7: =IFERROR(VLOOKUP($C7,薬効分類マスタ!$A$2:$B$180,2,FALSE()),"未登録") -> 催眠鎮静剤,抗不安剤 | E7: エスタゾラム | F7: ２ｍｇ１錠 | G7: ユーロジン２ｍｇ錠 | H7: Ｔ’ｓ製薬 | I7: 7.4 | J7: 先発品 | K7: =IFERROR(IF(VLOOKUP($C7,薬効分類マスタ!$A$2:$E$180,5,FALSE())=0,"",VLOOKUP($C7,薬効分類マスタ!$A$2:$E$180,5,FALSE())),"") | M7: =IF($K7="","",IF($L7<>"",$L7,VLOOKUP($C7,薬効分類マスタ!$A$2:$F$180,6,FALSE()))) | N7: =ASC(G7) -> ﾕｰﾛｼﾞﾝ2mg錠 | O7: =ASC(E7) -> ｴｽﾀｿﾞﾗﾑ | P7: =N(P6)+IF($C7=検索!$B$49,1,0) -> 0
A8: 内用薬 | B8: 1124001F2037 | C8: 112 | D8: =IFERROR(VLOOKUP($C8,薬効分類マスタ!$A$2:$B$180,2,FALSE()),"未登録") -> 催眠鎮静剤,抗不安剤 | E8: エスタゾラム | F8: ２ｍｇ１錠 | G8: エスタゾラム錠２ｍｇ「アメル」 | H8: 共和薬品工業 | I8: 6.3 | J8: 後発品 | K8: =IFERROR(IF(VLOOKUP($C8,薬効分類マスタ!$A$2:$E$180,5,FALSE())=0,"",VLOOKUP($C8,薬効分類マスタ!$A$2:$E$180,5,FALSE())),"") | M8: =IF($K8="","",IF($L8<>"",$L8,VLOOKUP($C8,薬効分類マスタ!$A$2:$F$180,6,FALSE()))) | N8: =ASC(G8) -> ｴｽﾀｿﾞﾗﾑ錠2mg｢ｱﾒﾙ｣ | O8: =ASC(E8) -> ｴｽﾀｿﾞﾗﾑ | P8: =N(P7)+IF($C8=検索!$B$49,1,0) -> 0
A9: 内用薬 | B9: 1124002M2022 | C9: 112 | D9: =IFERROR(VLOOKUP($C9,薬効分類マスタ!$A$2:$B$180,2,FALSE()),"未登録") -> 催眠鎮静剤,抗不安剤 | E9: フルラゼパム塩酸塩 | F9: １５ｍｇ１カプセル | G9: ダルメートカプセル１５ | H9: 共和薬品工業 | I9: 6.3 | J9: 先発品 | K9: =IFERROR(IF(VLOOKUP($C9,薬効分類マスタ!$A$2:$E$180,5,FALSE())=0,"",VLOOKUP($C9,薬効分類マスタ!$A$2:$E$180,5,FALSE())),"") | M9: =IF($K9="","",IF($L9<>"",$L9,VLOOKUP($C9,薬効分類マスタ!$A$2:$F$180,6,FALSE()))) | N9: =ASC(G9) -> ﾀﾞﾙﾒｰﾄｶﾌﾟｾﾙ15 | O9: =ASC(E9) -> ﾌﾙﾗｾﾞﾊﾟﾑ塩酸塩 | P9: =N(P8)+IF($C9=検索!$B$49,1,0) -> 0
A10: 内用薬 | B10: 1124003C1017 | C10: 112 | D10: =IFERROR(VLOOKUP($C10,薬効分類マスタ!$A$2:$B$180,2,FALSE()),"未登録") -> 催眠鎮静剤,抗不安剤 | E10: ニトラゼパム | F10: １％１ｇ | G10: ニトラゼパム１％細粒 | I10: 16.2 | K10: =IFERROR(IF(VLOOKUP($C10,薬効分類マスタ!$A$2:$E$180,5,FALSE())=0,"",VLOOKUP($C10,薬効分類マスタ!$A$2:$E$180,5,FALSE())),"") | M10: =IF($K10="","",IF($L10<>"",$L10,VLOOKUP($C10,薬効分類マスタ!$A$2:$F$180,6,FALSE()))) | N10: =ASC(G10) -> ﾆﾄﾗｾﾞﾊﾟﾑ1%細粒 | O10: =ASC(E10) -> ﾆﾄﾗｾﾞﾊﾟﾑ | P10: =N(P9)+IF($C10=検索!$B$49,1,0) -> 0
A11: 内用薬 | B11: 1124003C1092 | C11: 112 | D11: =IFERROR(VLOOKUP($C11,薬効分類マスタ!$A$2:$B$180,2,FALSE()),"未登録") -> 催眠鎮静剤,抗不安剤 | E11: ニトラゼパム | F11: １％１ｇ | G11: ベンザリン細粒１％ | H11: 共和薬品工業 | I11: 21.1 | K11: =IFERROR(IF(VLOOKUP($C11,薬効分類マスタ!$A$2:$E$180,5,FALSE())=0,"",VLOOKUP($C11,薬効分類マスタ!$A$2:$E$180,5,FALSE())),"") | M11: =IF($K11="","",IF($L11<>"",$L11,VLOOKUP($C11,薬効分類マスタ!$A$2:$F$180,6,FALSE()))) | N11: =ASC(G11) -> ﾍﾞﾝｻﾞﾘﾝ細粒1% | O11: =ASC(E11) -> ﾆﾄﾗｾﾞﾊﾟﾑ | P11: =N(P10)+IF($C11=検索!$B$49,1,0) -> 0
A12: 内用薬 | B12: 1124003F1021 | C12: 112 | D12: =IFERROR(VLOOKUP($C12,薬効分類マスタ!$A$2:$B$180,2,FALSE()),"未登録") -> 催眠鎮静剤,抗不安剤 | E12: ニトラゼパム | F12: ２ｍｇ１錠 | G12: ベンザリン錠２ | H12: 共和薬品工業 | I12: 7.9 | K12: =IFERROR(IF(VLOOKUP($C12,薬効分類マスタ!$A$2:$E$180,5,FALSE())=0,"",VLOOKUP($C12,薬効分類マスタ!$A$2:$E$180,5,FALSE())),"") | M12: =IF($K12="","",IF($L12<>"",$L12,VLOOKUP($C12,薬効分類マスタ!$A$2:$F$180,6,FALSE()))) | N12: =ASC(G12) -> ﾍﾞﾝｻﾞﾘﾝ錠2 | O12: =ASC(E12) -> ﾆﾄﾗｾﾞﾊﾟﾑ | P12: =N(P11)+IF($C12=検索!$B$49,1,0) -> 0
A13: 内用薬 | B13: 1124003F2010 | C13: 112 | D13: =IFERROR(VLOOKUP($C13,薬効分類マスタ!$A$2:$B$180,2,FALSE()),"未登録") -> 催眠鎮静剤,抗不安剤 | E13: ニトラゼパム | F13: ５ｍｇ１錠 | G13: ニトラゼパム５ｍｇ錠 | I13: 6.3 | J13: 後発品 | K13: =IFERROR(IF(VLOOKUP($C13,薬効分類マスタ!$A$2:$E$180,5,FALSE())=0,"",VLOOKUP($C13,薬効分類マスタ!$A$2:$E$180,5,FALSE())),"") | M13: =IF($K13="","",IF($L13<>"",$L13,VLOOKUP($C13,薬効分類マスタ!$A$2:$F$180,6,FALSE()))) | N13: =ASC(G13) -> ﾆﾄﾗｾﾞﾊﾟﾑ5mg錠 | O13: =ASC(E13) -> ﾆﾄﾗｾﾞﾊﾟﾑ | P13: =N(P12)+IF($C13=検索!$B$49,1,0) -> 0
A14: 内用薬 | B14: 1124003F2222 | C14: 112 | D14: =IFERROR(VLOOKUP($C14,薬効分類マスタ!$A$2:$B$180,2,FALSE()),"未登録") -> 催眠鎮静剤,抗不安剤 | E14: ニトラゼパム | F14: ５ｍｇ１錠 | G14: ベンザリン錠５ | H14: 共和薬品工業 | I14: 7.2 | J14: 先発品 | K14: =IFERROR(IF(VLOOKUP($C14,薬効分類マスタ!$A$2:$E$180,5,FALSE())=0,"",VLOOKUP($C14,薬効分類マスタ!$A$2:$E$180,5,FALSE())),"") | M14: =IF($K14="","",IF($L14<>"",$L14,VLOOKUP($C14,薬効分類マスタ!$A$2:$F$180,6,FALSE()))) | N14: =ASC(G14) -> ﾍﾞﾝｻﾞﾘﾝ錠5 | O14: =ASC(E14) -> ﾆﾄﾗｾﾞﾊﾟﾑ | P14: =N(P13)+IF($C14=検索!$B$49,1,0) -> 0
A15: 内用薬 | B15: 1124003F3016 | C15: 112 | D15: =IFERROR(VLOOKUP($C15,薬効分類マスタ!$A$2:$B$180,2,FALSE()),"未登録") -> 催眠鎮静剤,抗不安剤 | E15: ニトラゼパム | F15: １０ｍｇ１錠 | G15: ニトラゼパム１０ｍｇ錠 | I15: 6.3 | J15: 後発品 | K15: =IFERROR(IF(VLOOKUP($C15,薬効分類マスタ!$A$2:$E$180,5,FALSE())=0,"",VLOOKUP($C15,薬効分類マスタ!$A$2:$E$180,5,FALSE())),"") | M15: =IF($K15="","",IF($L15<>"",$L15,VLOOKUP($C15,薬効分類マスタ!$A$2:$F$180,6,FALSE()))) | N15: =ASC(G15) -> ﾆﾄﾗｾﾞﾊﾟﾑ10mg錠 | O15: =ASC(E15) -> ﾆﾄﾗｾﾞﾊﾟﾑ | P15: =N(P14)+IF($C15=検索!$B$49,1,0) -> 0
A16: 内用薬 | B16: 1124003F3121 | C16: 112 | D16: =IFERROR(VLOOKUP($C16,薬効分類マスタ!$A$2:$B$180,2,FALSE()),"未登録") -> 催眠鎮静剤,抗不安剤 | E16: ニトラゼパム | F16: １０ｍｇ１錠 | G16: ベンザリン錠１０ | H16: 共和薬品工業 | I16: 11.7 | J16: 先発品 | K16: =IFERROR(IF(VLOOKUP($C16,薬効分類マスタ!$A$2:$E$180,5,FALSE())=0,"",VLOOKUP($C16,薬効分類マスタ!$A$2:$E$180,5,FALSE())),"") | M16: =IF($K16="","",IF($L16<>"",$L16,VLOOKUP($C16,薬効分類マスタ!$A$2:$F$180,6,FALSE()))) | N16: =ASC(G16) -> ﾍﾞﾝｻﾞﾘﾝ錠10 | O16: =ASC(E16) -> ﾆﾄﾗｾﾞﾊﾟﾑ | P16: =N(P15)+IF($C16=検索!$B$49,1,0) -> 0
A17: 内用薬 | B17: 1124007F1011 | C17: 112 | D17: =IFERROR(VLOOKUP($C17,薬効分類マスタ!$A$2:$B$180,2,FALSE()),"未登録") -> 催眠鎮静剤,抗不安剤 | E17: トリアゾラム | F17: ０．１２５ｍｇ１錠 | G17: トリアゾラム０．１２５ｍｇ錠 | I17: 6.1 | J17: 後発品 | K17: =IFERROR(IF(VLOOKUP($C17,薬効分類マスタ!$A$2:$E$180,5,FALSE())=0,"",VLOOKUP($C17,薬効分類マスタ!$A$2:$E$180,5,FALSE())),"") | M17: =IF($K17="","",IF($L17<>"",$L17,VLOOKUP($C17,薬効分類マスタ!$A$2:$F$180,6,FALSE()))) | N17: =ASC(G17) -> ﾄﾘｱｿﾞﾗﾑ0.125mg錠 | O17: =ASC(E17) -> ﾄﾘｱｿﾞﾗﾑ | P17: =N(P16)+IF($C17=検索!$B$49,1,0) -> 0
A18: 内用薬 | B18: 1124007F1020 | C18: 112 | D18: =IFERROR(VLOOKUP($C18,薬効分類マスタ!$A$2:$B$180,2,FALSE()),"未登録") -> 催眠鎮静剤,抗不安剤 | E18: トリアゾラム | F18: ０．１２５ｍｇ１錠 | G18: ハルシオン０．１２５ｍｇ錠 | H18: ファイザー | I18: 6.3 | J18: 先発品 | K18: =IFERROR(IF(VLOOKUP($C18,薬効分類マスタ!$A$2:$E$180,5,FALSE())=0,"",VLOOKUP($C18,薬効分類マスタ!$A$2:$E$180,5,FALSE())),"") | M18: =IF($K18="","",IF($L18<>"",$L18,VLOOKUP($C18,薬効分類マスタ!$A$2:$F$180,6,FALSE()))) | N18: =ASC(G18) -> ﾊﾙｼｵﾝ0.125mg錠 | O18: =ASC(E18) -> ﾄﾘｱｿﾞﾗﾑ | P18: =N(P17)+IF($C18=検索!$B$49,1,0) -> 0
A19: 内用薬 | B19: 1124007F2018 | C19: 112 | D19: =IFERROR(VLOOKUP($C19,薬効分類マスタ!$A$2:$B$180,2,FALSE()),"未登録") -> 催眠鎮静剤,抗不安剤 | E19: トリアゾラム | F19: ０．２５ｍｇ１錠 | G19: トリアゾラム０．２５ｍｇ錠 | I19: 6.3 | J19: 後発品 | K19: =IFERROR(IF(VLOOKUP($C19,薬効分類マスタ!$A$2:$E$180,5,FALSE())=0,"",VLOOKUP($C19,薬効分類マスタ!$A$2:$E$180,5,FALSE())),"") | M19: =IF($K19="","",IF($L19<>"",$L19,VLOOKUP($C19,薬効分類マスタ!$A$2:$F$180,6,FALSE()))) | N19: =ASC(G19) -> ﾄﾘｱｿﾞﾗﾑ0.25mg錠 | O19: =ASC(E19) -> ﾄﾘｱｿﾞﾗﾑ | P19: =N(P18)+IF($C19=検索!$B$49,1,0) -> 0
A20: 内用薬 | B20: 1124007F2026 | C20: 112 | D20: =IFERROR(VLOOKUP($C20,薬効分類マスタ!$A$2:$B$180,2,FALSE()),"未登録") -> 催眠鎮静剤,抗不安剤 | E20: トリアゾラム | F20: ０．２５ｍｇ１錠 | G20: ハルシオン０．２５ｍｇ錠 | H20: ファイザー | I20: 6.4 | J20: 先発品 | K20: =IFERROR(IF(VLOOKUP($C20,薬効分類マスタ!$A$2:$E$180,5,FALSE())=0,"",VLOOKUP($C20,薬効分類マスタ!$A$2:$E$180,5,FALSE())),"") | M20: =IF($K20="","",IF($L20<>"",$L20,VLOOKUP($C20,薬効分類マスタ!$A$2:$F$180,6,FALSE()))) | N20: =ASC(G20) -> ﾊﾙｼｵﾝ0.25mg錠 | O20: =ASC(E20) -> ﾄﾘｱｿﾞﾗﾑ | P20: =N(P19)+IF($C20=検索!$B$49,1,0) -> 0
A21: 内用薬 | B21: 1124008F1016 | C21: 112 | D21: =IFERROR(VLOOKUP($C21,薬効分類マスタ!$A$2:$B$180,2,FALSE()),"未登録") -> 催眠鎮静剤,抗不安剤 | E21: フルニトラゼパム | F21: １ｍｇ１錠 | G21: フルニトラゼパム１ｍｇ錠 | I21: 6.1 | J21: 後発品 | K21: =IFERROR(IF(VLOOKUP($C21,薬効分類マスタ!$A$2:$E$180,5,FALSE())=0,"",VLOOKUP($C21,薬効分類マスタ!$A$2:$E$180,5,FALSE())),"") | M21: =IF($K21="","",IF($L21<>"",$L21,VLOOKUP($C21,薬効分類マスタ!$A$2:$F$180,6,FALSE()))) | N21: =ASC(G21) -> ﾌﾙﾆﾄﾗｾﾞﾊﾟﾑ1mg錠 | O21: =ASC(E21) -> ﾌﾙﾆﾄﾗｾﾞﾊﾟﾑ | P21: =N(P20)+IF($C21=検索!$B$49,1,0) -> 0
A22: 内用薬 | B22: 1124008F1024 | C22: 112 | D22: =IFERROR(VLOOKUP($C22,薬効分類マスタ!$A$2:$B$180,2,FALSE()),"未登録") -> 催眠鎮静剤,抗不安剤 | E22: フルニトラゼパム | F22: １ｍｇ１錠 | G22: サイレース錠１ｍｇ | H22: エーザイ | I22: 6.4 | J22: 先発品 | K22: =IFERROR(IF(VLOOKUP($C22,薬効分類マスタ!$A$2:$E$180,5,FALSE())=0,"",VLOOKUP($C22,薬効分類マスタ!$A$2:$E$180,5,FALSE())),"") | M22: =IF($K22="","",IF($L22<>"",$L22,VLOOKUP($C22,薬効分類マスタ!$A$2:$F$180,6,FALSE()))) | N22: =ASC(G22) -> ｻｲﾚｰｽ錠1mg | O22: =ASC(E22) -> ﾌﾙﾆﾄﾗｾﾞﾊﾟﾑ | P22: =N(P21)+IF($C22=検索!$B$49,1,0) -> 0
A23: 内用薬 | B23: 1124008F2012 | C23: 112 | D23: =IFERROR(VLOOKUP($C23,薬効分類マスタ!$A$2:$B$180,2,FALSE()),"未登録") -> 催眠鎮静剤,抗不安剤 | E23: フルニトラゼパム | F23: ２ｍｇ１錠 | G23: フルニトラゼパム２ｍｇ錠 | I23: 6.3 | J23: 後発品 | K23: =IFERROR(IF(VLOOKUP($C23,薬効分類マスタ!$A$2:$E$180,5,FALSE())=0,"",VLOOKUP($C23,薬効分類マスタ!$A$2:$E$180,5,FALSE())),"") | M23: =IF($K23="","",IF($L23<>"",$L23,VLOOKUP($C23,薬効分類マスタ!$A$2:$F$180,6,FALSE()))) | N23: =ASC(G23) -> ﾌﾙﾆﾄﾗｾﾞﾊﾟﾑ2mg錠 | O23: =ASC(E23) -> ﾌﾙﾆﾄﾗｾﾞﾊﾟﾑ | P23: =N(P22)+IF($C23=検索!$B$49,1,0) -> 0
A24: 内用薬 | B24: 1124008F2020 | C24: 112 | D24: =IFERROR(VLOOKUP($C24,薬効分類マスタ!$A$2:$B$180,2,FALSE()),"未登録") -> 催眠鎮静剤,抗不安剤 | E24: フルニトラゼパム | F24: ２ｍｇ１錠 | G24: サイレース錠２ｍｇ | H24: エーザイ | I24: 7.4 | J24: 先発品 | K24: =IFERROR(IF(VLOOKUP($C24,薬効分類マスタ!$A$2:$E$180,5,FALSE())=0,"",VLOOKUP($C24,薬効分類マスタ!$A$2:$E$180,5,FALSE())),"") | M24: =IF($K24="","",IF($L24<>"",$L24,VLOOKUP($C24,薬効分類マスタ!$A$2:$F$180,6,FALSE()))) | N24: =ASC(G24) -> ｻｲﾚｰｽ錠2mg | O24: =ASC(E24) -> ﾌﾙﾆﾄﾗｾﾞﾊﾟﾑ | P24: =N(P23)+IF($C24=検索!$B$49,1,0) -> 0
A25: 内用薬 | B25: 1124009F1010 | C25: 112 | D25: =IFERROR(VLOOKUP($C25,薬効分類マスタ!$A$2:$B$180,2,FALSE()),"未登録") -> 催眠鎮静剤,抗不安剤 | E25: ブロチゾラム | F25: ０．２５ｍｇ１錠 | G25: ブロチゾラム０．２５ｍｇ錠 | I25: 10.8 | J25: 後発品 | K25: =IFERROR(IF(VLOOKUP($C25,薬効分類マスタ!$A$2:$E$180,5,FALSE())=0,"",VLOOKUP($C25,薬効分類マスタ!$A$2:$E$180,5,FALSE())),"") | M25: =IF($K25="","",IF($L25<>"",$L25,VLOOKUP($C25,薬効分類マスタ!$A$2:$F$180,6,FALSE()))) | N25: =ASC(G25) -> ﾌﾞﾛﾁｿﾞﾗﾑ0.25mg錠 | O25: =ASC(E25) -> ﾌﾞﾛﾁｿﾞﾗﾑ | P25: =N(P24)+IF($C25=検索!$B$49,1,0) -> 0
A26: 内用薬 | B26: 1124009F1223 | C26: 112 | D26: =IFERROR(VLOOKUP($C26,薬効分類マスタ!$A$2:$B$180,2,FALSE()),"未登録") -> 催眠鎮静剤,抗不安剤 | E26: ブロチゾラム | F26: ０．２５ｍｇ１錠 | G26: レンドルミン錠０．２５ｍｇ | H26: 日本ベーリンガーインゲルハイム | I26: 10.8 | J26: 先発品 | K26: =IFERROR(IF(VLOOKUP($C26,薬効分類マスタ!$A$2:$E$180,5,FALSE())=0,"",VLOOKUP($C26,薬効分類マスタ!$A$2:$E$180,5,FALSE())),"") | M26: =IF($K26="","",IF($L26<>"",$L26,VLOOKUP($C26,薬効分類マスタ!$A$2:$F$180,6,FALSE()))) | N26: =ASC(G26) -> ﾚﾝﾄﾞﾙﾐﾝ錠0.25mg | O26: =ASC(E26) -> ﾌﾞﾛﾁｿﾞﾗﾑ | P26: =N(P25)+IF($C26=検索!$B$49,1,0) -> 0
A27: 内用薬 | B27: 1124009F2017 | C27: 112 | D27: =IFERROR(VLOOKUP($C27,薬効分類マスタ!$A$2:$B$180,2,FALSE()),"未登録") -> 催眠鎮静剤,抗不安剤 | E27: ブロチゾラム | F27: ０．２５ｍｇ１錠 | G27: ブロチゾラム０．２５ｍｇ口腔内崩壊錠 | I27: 10.8 | J27: 後発品 | K27: =IFERROR(IF(VLOOKUP($C27,薬効分類マスタ!$A$2:$E$180,5,FALSE())=0,"",VLOOKUP($C27,薬効分類マスタ!$A$2:$E$180,5,FALSE())),"") | M27: =IF($K27="","",IF($L27<>"",$L27,VLOOKUP($C27,薬効分類マスタ!$A$2:$F$180,6,FALSE()))) | N27: =ASC(G27) -> ﾌﾞﾛﾁｿﾞﾗﾑ0.25mg口腔内崩壊錠 | O27: =ASC(E27) -> ﾌﾞﾛﾁｿﾞﾗﾑ | P27: =N(P26)+IF($C27=検索!$B$49,1,0) -> 0
A28: 内用薬 | B28: 1124009F2025 | C28: 112 | D28: =IFERROR(VLOOKUP($C28,薬効分類マスタ!$A$2:$B$180,2,FALSE()),"未登録") -> 催眠鎮静剤,抗不安剤 | E28: ブロチゾラム | F28: ０．２５ｍｇ１錠 | G28: レンドルミンＤ錠０．２５ｍｇ | H28: 日本ベーリンガーインゲルハイム | I28: 10.8 | J28: 先発品 | K28: =IFERROR(IF(VLOOKUP($C28,薬効分類マスタ!$A$2:$E$180,5,FALSE())=0,"",VLOOKUP($C28,薬効分類マスタ!$A$2:$E$180,5,FALSE())),"") | M28: =IF($K28="","",IF($L28<>"",$L28,VLOOKUP($C28,薬効分類マスタ!$A$2:$F$180,6,FALSE()))) | N28: =ASC(G28) -> ﾚﾝﾄﾞﾙﾐﾝD錠0.25mg | O28: =ASC(E28) -> ﾌﾞﾛﾁｿﾞﾗﾑ | P28: =N(P27)+IF($C28=検索!$B$49,1,0) -> 0
A29: 内用薬 | B29: 1124010F1021 | C29: 112 | D29: =IFERROR(VLOOKUP($C29,薬効分類マスタ!$A$2:$B$180,2,FALSE()),"未登録") -> 催眠鎮静剤,抗不安剤 | E29: ロルメタゼパム | F29: １ｍｇ１錠 | G29: エバミール錠１．０ | H29: 丸石製薬 | I29: 9.5 | J29: 先発品 | K29: =IFERROR(IF(VLOOKUP($C29,薬効分類マスタ!$A$2:$E$180,5,FALSE())=0,"",VLOOKUP($C29,薬効分類マスタ!$A$2:$E$180,5,FALSE())),"") | M29: =IF($K29="","",IF($L29<>"",$L29,VLOOKUP($C29,薬効分類マスタ!$A$2:$F$180,6,FALSE()))) | N29: =ASC(G29) -> ｴﾊﾞﾐｰﾙ錠1.0 | O29: =ASC(E29) -> ﾛﾙﾒﾀｾﾞﾊﾟﾑ | P29: =N(P28)+IF($C29=検索!$B$49,1,0) -> 0
A30: 内用薬 | B30: 1124010F1030 | C30: 112 | D30: =IFERROR(VLOOKUP($C30,薬効分類マスタ!$A$2:$B$180,2,FALSE()),"未登録") -> 催眠鎮静剤,抗不安剤 | E30: ロルメタゼパム | F30: １ｍｇ１錠 | G30: ロラメット錠１．０ | H30: あすか製薬 | I30: 12.5 | J30: 先発品 | K30: =IFERROR(IF(VLOOKUP($C30,薬効分類マスタ!$A$2:$E$180,5,FALSE())=0,"",VLOOKUP($C30,薬効分類マスタ!$A$2:$E$180,5,FALSE())),"") | M30: =IF($K30="","",IF($L30<>"",$L30,VLOOKUP($C30,薬効分類マスタ!$A$2:$F$180,6,FALSE()))) | N30: =ASC(G30) -> ﾛﾗﾒｯﾄ錠1.0 | O30: =ASC(E30) -> ﾛﾙﾒﾀｾﾞﾊﾟﾑ | P30: =N(P29)+IF($C30=検索!$B$49,1,0) -> 0
A31: 内用薬 | B31: 1124013B1031 | C31: 112 | D31: =IFERROR(VLOOKUP($C31,薬効分類マスタ!$A$2:$B$180,2,FALSE()),"未登録") -> 催眠鎮静剤,抗不安剤 | E31: オキサゾラム | F31: １０％１ｇ | G31: セレナール散１０％ | H31: アルフレッサファーマ | I31: 22.5 | J31: 先発品 | K31: =IFERROR(IF(VLOOKUP($C31,薬効分類マスタ!$A$2:$E$180,5,FALSE())=0,"",VLOOKUP($C31,薬効分類マスタ!$A$2:$E$180,5,FALSE())),"") | M31: =IF($K31="","",IF($L31<>"",$L31,VLOOKUP($C31,薬効分類マスタ!$A$2:$F$180,6,FALSE()))) | N31: =ASC(G31) -> ｾﾚﾅｰﾙ散10% | O31: =ASC(E31) -> ｵｷｻｿﾞﾗﾑ | P31: =N(P30)+IF($C31=検索!$B$49,1,0) -> 0
A32: 内用薬 | B32: 1124013F1033 | C32: 112 | D32: =IFERROR(VLOOKUP($C32,薬効分類マスタ!$A$2:$B$180,2,FALSE()),"未登録") -> 催眠鎮静剤,抗不安剤 | E32: オキサゾラム | F32: ５ｍｇ１錠 | G32: セレナール錠５ | H32: アルフレッサファーマ | I32: 6.3 | J32: 先発品 | K32: =IFERROR(IF(VLOOKUP($C32,薬効分類マスタ!$A$2:$E$180,5,FALSE())=0,"",VLOOKUP($C32,薬効分類マスタ!$A$2:$E$180,5,FALSE())),"") | M32: =IF($K32="","",IF($L32<>"",$L32,VLOOKUP($C32,薬効分類マスタ!$A$2:$F$180,6,FALSE()))) | N32: =ASC(G32) -> ｾﾚﾅｰﾙ錠5 | O32: =ASC(E32) -> ｵｷｻｿﾞﾗﾑ | P32: =N(P31)+IF($C32=検索!$B$49,1,0) -> 0
A33: 内用薬 | B33: 1124013F2064 | C33: 112 | D33: =IFERROR(VLOOKUP($C33,薬効分類マスタ!$A$2:$B$180,2,FALSE()),"未登録") -> 催眠鎮静剤,抗不安剤 | E33: オキサゾラム | F33: １０ｍｇ１錠 | G33: セレナール錠１０ | H33: アルフレッサファーマ | I33: 6.3 | J33: 先発品 | K33: =IFERROR(IF(VLOOKUP($C33,薬効分類マスタ!$A$2:$E$180,5,FALSE())=0,"",VLOOKUP($C33,薬効分類マスタ!$A$2:$E$180,5,FALSE())),"") | M33: =IF($K33="","",IF($L33<>"",$L33,VLOOKUP($C33,薬効分類マスタ!$A$2:$F$180,6,FALSE()))) | N33: =ASC(G33) -> ｾﾚﾅｰﾙ錠10 | O33: =ASC(E33) -> ｵｷｻｿﾞﾗﾑ | P33: =N(P32)+IF($C33=検索!$B$49,1,0) -> 0
A34: 内用薬 | B34: 1124014B1036 | C34: 112 | D34: =IFERROR(VLOOKUP($C34,薬効分類マスタ!$A$2:$B$180,2,FALSE()),"未登録") -> 催眠鎮静剤,抗不安剤 | E34: クロキサゾラム | F34: １％１ｇ | G34: セパゾン散１％ | H34: アルフレッサファーマ | I34: 16.6 | J34: 先発品 | K34: =IFERROR(IF(VLOOKUP($C34,薬効分類マスタ!$A$2:$E$180,5,FALSE())=0,"",VLOOKUP($C34,薬効分類マスタ!$A$2:$E$180,5,FALSE())),"") | M34: =IF($K34="","",IF($L34<>"",$L34,VLOOKUP($C34,薬効分類マスタ!$A$2:$F$180,6,FALSE()))) | N34: =ASC(G34) -> ｾﾊﾟｿﾞﾝ散1% | O34: =ASC(E34) -> ｸﾛｷｻｿﾞﾗﾑ | P34: =N(P33)+IF($C34=検索!$B$49,1,0) -> 0
A35: 内用薬 | B35: 1124014F1038 | C35: 112 | D35: =IFERROR(VLOOKUP($C35,薬効分類マスタ!$A$2:$B$180,2,FALSE()),"未登録") -> 催眠鎮静剤,抗不安剤 | E35: クロキサゾラム | F35: １ｍｇ１錠 | G35: セパゾン錠１ | H35: アルフレッサファーマ | I35: 6.3 | J35: 先発品 | K35: =IFERROR(IF(VLOOKUP($C35,薬効分類マスタ!$A$2:$E$180,5,FALSE())=0,"",VLOOKUP($C35,薬効分類マスタ!$A$2:$E$180,5,FALSE())),"") | M35: =IF($K35="","",IF($L35<>"",$L35,VLOOKUP($C35,薬効分類マスタ!$A$2:$F$180,6,FALSE()))) | N35: =ASC(G35) -> ｾﾊﾟｿﾞﾝ錠1 | O35: =ASC(E35) -> ｸﾛｷｻｿﾞﾗﾑ | P35: =N(P34)+IF($C35=検索!$B$49,1,0) -> 0
A36: 内用薬 | B36: 1124014F2034 | C36: 112 | D36: =IFERROR(VLOOKUP($C36,薬効分類マスタ!$A$2:$B$180,2,FALSE()),"未登録") -> 催眠鎮静剤,抗不安剤 | E36: クロキサゾラム | F36: ２ｍｇ１錠 | G36: セパゾン錠２ | H36: アルフレッサファーマ | I36: 6.3 | J36: 先発品 | K36: =IFERROR(IF(VLOOKUP($C36,薬効分類マスタ!$A$2:$E$180,5,FALSE())=0,"",VLOOKUP($C36,薬効分類マスタ!$A$2:$E$180,5,FALSE())),"") | M36: =IF($K36="","",IF($L36<>"",$L36,VLOOKUP($C36,薬効分類マスタ!$A$2:$F$180,6,FALSE()))) | N36: =ASC(G36) -> ｾﾊﾟｿﾞﾝ錠2 | O36: =ASC(E36) -> ｸﾛｷｻｿﾞﾗﾑ | P36: =N(P35)+IF($C36=検索!$B$49,1,0) -> 0
A37: 内用薬 | B37: 1124015M2038 | C37: 112 | D37: =IFERROR(VLOOKUP($C37,薬効分類マスタ!$A$2:$B$180,2,FALSE()),"未登録") -> 催眠鎮静剤,抗不安剤 | E37: クロラゼプ酸二カリウム | F37: ７．５ｍｇ１カプセル | G37: メンドンカプセル７．５ｍｇ | H37: ヴィアトリス製薬 | I37: 10.8 | J37: 先発品 | K37: =IFERROR(IF(VLOOKUP($C37,薬効分類マスタ!$A$2:$E$180,5,FALSE())=0,"",VLOOKUP($C37,薬効分類マスタ!$A$2:$E$180,5,FALSE())),"") | M37: =IF($K37="","",IF($L37<>"",$L37,VLOOKUP($C37,薬効分類マスタ!$A$2:$F$180,6,FALSE()))) | N37: =ASC(G37) -> ﾒﾝﾄﾞﾝｶﾌﾟｾﾙ7.5mg | O37: =ASC(E37) -> ｸﾛﾗｾﾞﾌﾟ酸二ｶﾘｳﾑ | P37: =N(P36)+IF($C37=検索!$B$49,1,0) -> 0
A38: 内用薬 | B38: 1124017B1129 | C38: 112 | D38: =IFERROR(VLOOKUP($C38,薬効分類マスタ!$A$2:$B$180,2,FALSE()),"未登録") -> 催眠鎮静剤,抗不安剤 | E38: ジアゼパム | F38: １％１ｇ | G38: セルシン散１％ | H38: Ｔ’ｓ製薬 | I38: 9.4 | K38: =IFERROR(IF(VLOOKUP($C38,薬効分類マスタ!$A$2:$E$180,5,FALSE())=0,"",VLOOKUP($C38,薬効分類マスタ!$A$2:$E$180,5,FALSE())),"") | M38: =IF($K38="","",IF($L38<>"",$L38,VLOOKUP($C38,薬効分類マスタ!$A$2:$F$180,6,FALSE()))) | N38: =ASC(G38) -> ｾﾙｼﾝ散1% | O38: =ASC(E38) -> ｼﾞｱｾﾞﾊﾟﾑ | P38: =N(P37)+IF($C38=検索!$B$49,1,0) -> 0
A39: 内用薬 | B39: 1124017B1145 | C39: 112 | D39: =IFERROR(VLOOKUP($C39,薬効分類マスタ!$A$2:$B$180,2,FALSE()),"未登録") -> 催眠鎮静剤,抗不安剤 | E39: ジアゼパム | F39: １％１ｇ | G39: ホリゾン散１％ | H39: 丸石製薬 | I39: 10.6 | K39: =IFERROR(IF(VLOOKUP($C39,薬効分類マスタ!$A$2:$E$180,5,FALSE())=0,"",VLOOKUP($C39,薬効分類マスタ!$A$2:$E$180,5,FALSE())),"") | M39: =IF($K39="","",IF($L39<>"",$L39,VLOOKUP($C39,薬効分類マスタ!$A$2:$F$180,6,FALSE()))) | N39: =ASC(G39) -> ﾎﾘｿﾞﾝ散1% | O39: =ASC(E39) -> ｼﾞｱｾﾞﾊﾟﾑ | P39: =N(P38)+IF($C39=検索!$B$49,1,0) -> 0
A40: 内用薬 | B40: 1124017F2011 | C40: 112 | D40: =IFERROR(VLOOKUP($C40,薬効分類マスタ!$A$2:$B$180,2,FALSE()),"未登録") -> 催眠鎮静剤,抗不安剤 | E40: ジアゼパム | F40: ２ｍｇ１錠 | G40: ジアゼパム２ｍｇ錠 | I40: 6.1 | J40: 後発品 | K40: =IFERROR(IF(VLOOKUP($C40,薬効分類マスタ!$A$2:$E$180,5,FALSE())=0,"",VLOOKUP($C40,薬効分類マスタ!$A$2:$E$180,5,FALSE())),"") | M40: =IF($K40="","",IF($L40<>"",$L40,VLOOKUP($C40,薬効分類マスタ!$A$2:$F$180,6,FALSE()))) | N40: =ASC(G40) -> ｼﾞｱｾﾞﾊﾟﾑ2mg錠 | O40: =ASC(E40) -> ｼﾞｱｾﾞﾊﾟﾑ | P40: =N(P39)+IF($C40=検索!$B$49,1,0) -> 0
...
